//////////////////////////////////////////////////////////////////
//////////////////////////////////////////////////////////////////
//////////////////////////////////////////////////////////////////

ERROR 000 : APPEAR AT END INTERACTION EVEN THOUGH NOT ANYTHING PROBLEMATIC DURING INTERACTION (without problematic bits...)


021-03-07 16:08:22.540 | INFO     |  4936 | AssociativeFallback | Thanks for this interaction.
2021-03-07 16:08:31.420 | INFO     |  4936 | mycroft.skills.skill_manager:send:64 | New Settings meta to upload.
2021-03-07 16:08:47.765 | ERROR    |  4936 | mycroft.skills.settings:_issue_api_call:306 | Failed to upload skill settings meta for @efac3f39-a15a-4151-9ba6-403d7a85c0b2|fallback-associative
Traceback (most recent call last):
  File "/home/unfamiliarconvenient/mycroft-core/.venv/lib/python3.8/site-packages/urllib3/connectionpool.py", line 426, in _make_request
    six.raise_from(e, None)
  File "<string>", line 3, in raise_from
  File "/home/unfamiliarconvenient/mycroft-core/.venv/lib/python3.8/site-packages/urllib3/connectionpool.py", line 421, in _make_request
    httplib_response = conn.getresponse()
  File "/usr/lib/python3.8/http/client.py", line 1347, in getresponse
    response.begin()
  File "/usr/lib/python3.8/http/client.py", line 307, in begin
    version, status, reason = self._read_status()
  File "/usr/lib/python3.8/http/client.py", line 268, in _read_status
    line = str(self.fp.readline(_MAXLINE + 1), "iso-8859-1")
  File "/usr/lib/python3.8/socket.py", line 669, in readinto
    return self._sock.recv_into(b)
  File "/usr/lib/python3.8/ssl.py", line 1241, in recv_into
    return self.read(nbytes, buffer)
  File "/usr/lib/python3.8/ssl.py", line 1099, in read
    return self._sslobj.read(len, buffer)
socket.timeout: The read operation timed out

During handling of the above exception, another exception occurred:

Traceback (most recent call last):
  File "/home/unfamiliarconvenient/mycroft-core/.venv/lib/python3.8/site-packages/requests/adapters.py", line 439, in send
    resp = conn.urlopen(
  File "/home/unfamiliarconvenient/mycroft-core/.venv/lib/python3.8/site-packages/urllib3/connectionpool.py", line 724, in urlopen
    retries = retries.increment(
  File "/home/unfamiliarconvenient/mycroft-core/.venv/lib/python3.8/site-packages/urllib3/util/retry.py", line 403, in increment
    raise six.reraise(type(error), error, _stacktrace)
  File "/home/unfamiliarconvenient/mycroft-core/.venv/lib/python3.8/site-packages/urllib3/packages/six.py", line 735, in reraise
    raise value
  File "/home/unfamiliarconvenient/mycroft-core/.venv/lib/python3.8/site-packages/urllib3/connectionpool.py", line 670, in urlopen
    httplib_response = self._make_request(
  File "/home/unfamiliarconvenient/mycroft-core/.venv/lib/python3.8/site-packages/urllib3/connectionpool.py", line 428, in _make_request
    self._raise_timeout(err=e, url=url, timeout_value=read_timeout)
  File "/home/unfamiliarconvenient/mycroft-core/.venv/lib/python3.8/site-packages/urllib3/connectionpool.py", line 335, in _raise_timeout
    raise ReadTimeoutError(
urllib3.exceptions.ReadTimeoutError: HTTPSConnectionPool(host='api.mycroft.ai', port=443): Read timed out. (read timeout=15)

During handling of the above exception, another exception occurred:

Traceback (most recent call last):
  File "/home/unfamiliarconvenient/mycroft-core/mycroft/skills/settings.py", line 304, in _issue_api_call
    self.api.upload_skill_metadata(self.settings_meta)
  File "/home/unfamiliarconvenient/mycroft-core/mycroft/api/__init__.py", line 379, in upload_skill_metadata
    return self.request({
  File "/home/unfamiliarconvenient/mycroft-core/mycroft/api/__init__.py", line 69, in request
    return self.send(params)
  File "/home/unfamiliarconvenient/mycroft-core/mycroft/api/__init__.py", line 139, in send
    response = requests.request(
  File "/home/unfamiliarconvenient/mycroft-core/.venv/lib/python3.8/site-packages/requests/api.py", line 61, in request
    return session.request(method=method, url=url, **kwargs)
  File "/home/unfamiliarconvenient/mycroft-core/.venv/lib/python3.8/site-packages/requests/sessions.py", line 530, in request
    resp = self.send(prep, **send_kwargs)
  File "/home/unfamiliarconvenient/mycroft-core/.venv/lib/python3.8/site-packages/requests/sessions.py", line 643, in send
    r = adapter.send(request, **kwargs)
  File "/home/unfamiliarconvenient/mycroft-core/.venv/lib/python3.8/site-packages/requests/adapters.py", line 529, in send
    raise ReadTimeout(e, request=request)
requests.exceptions.ReadTimeout: HTTPSConnectionPool(host='api.mycroft.ai', port=443): Read timed out. (read timeout=15)
2021-03-07 16:09:52.139 | ERROR    |  4936 | mycroft.skills.settings:_issue_api_call:306 | Failed to upload skill settings meta for @efac3f39-a15a-4151-9ba6-403d7a85c0b2|fallback-associative
Traceback (most recent call last):
  File "/home/unfamiliarconvenient/mycroft-core/.venv/lib/python3.8/site-packages/urllib3/connectionpool.py", line 381, in _make_request
    self._validate_conn(conn)
  File "/home/unfamiliarconvenient/mycroft-core/.venv/lib/python3.8/site-packages/urllib3/connectionpool.py", line 976, in _validate_conn
    conn.connect()
  File "/home/unfamiliarconvenient/mycroft-core/.venv/lib/python3.8/site-packages/urllib3/connection.py", line 361, in connect
    self.sock = ssl_wrap_socket(
  File "/home/unfamiliarconvenient/mycroft-core/.venv/lib/python3.8/site-packages/urllib3/util/ssl_.py", line 377, in ssl_wrap_socket
    return context.wrap_socket(sock, server_hostname=server_hostname)
  File "/usr/lib/python3.8/ssl.py", line 500, in wrap_socket
    return self.sslsocket_class._create(
  File "/usr/lib/python3.8/ssl.py", line 1040, in _create
    self.do_handshake()
  File "/usr/lib/python3.8/ssl.py", line 1309, in do_handshake
    self._sslobj.do_handshake()
socket.timeout: _ssl.c:1106: The handshake operation timed out

During handling of the above exception, another exception occurred:

Traceback (most recent call last):
  File "/home/unfamiliarconvenient/mycroft-core/.venv/lib/python3.8/site-packages/requests/adapters.py", line 439, in send
    resp = conn.urlopen(
  File "/home/unfamiliarconvenient/mycroft-core/.venv/lib/python3.8/site-packages/urllib3/connectionpool.py", line 724, in urlopen
    retries = retries.increment(
  File "/home/unfamiliarconvenient/mycroft-core/.venv/lib/python3.8/site-packages/urllib3/util/retry.py", line 403, in increment
    raise six.reraise(type(error), error, _stacktrace)
  File "/home/unfamiliarconvenient/mycroft-core/.venv/lib/python3.8/site-packages/urllib3/packages/six.py", line 735, in reraise
    raise value
  File "/home/unfamiliarconvenient/mycroft-core/.venv/lib/python3.8/site-packages/urllib3/connectionpool.py", line 670, in urlopen
    httplib_response = self._make_request(
  File "/home/unfamiliarconvenient/mycroft-core/.venv/lib/python3.8/site-packages/urllib3/connectionpool.py", line 384, in _make_request
    self._raise_timeout(err=e, url=url, timeout_value=conn.timeout)
  File "/home/unfamiliarconvenient/mycroft-core/.venv/lib/python3.8/site-packages/urllib3/connectionpool.py", line 335, in _raise_timeout
    raise ReadTimeoutError(
urllib3.exceptions.ReadTimeoutError: HTTPSConnectionPool(host='api.mycroft.ai', port=443): Read timed out. (read timeout=3.05)

During handling of the above exception, another exception occurred:

Traceback (most recent call last):
  File "/home/unfamiliarconvenient/mycroft-core/mycroft/skills/settings.py", line 304, in _issue_api_call
    self.api.upload_skill_metadata(self.settings_meta)
  File "/home/unfamiliarconvenient/mycroft-core/mycroft/api/__init__.py", line 379, in upload_skill_metadata
    return self.request({
  File "/home/unfamiliarconvenient/mycroft-core/mycroft/api/__init__.py", line 69, in request
    return self.send(params)
  File "/home/unfamiliarconvenient/mycroft-core/mycroft/api/__init__.py", line 139, in send
    response = requests.request(
  File "/home/unfamiliarconvenient/mycroft-core/.venv/lib/python3.8/site-packages/requests/api.py", line 61, in request
    return session.request(method=method, url=url, **kwargs)
  File "/home/unfamiliarconvenient/mycroft-core/.venv/lib/python3.8/site-packages/requests/sessions.py", line 530, in request
    resp = self.send(prep, **send_kwargs)
  File "/home/unfamiliarconvenient/mycroft-core/.venv/lib/python3.8/site-packages/requests/sessions.py", line 643, in send
    r = adapter.send(request, **kwargs)
  File "/home/unfamiliarconvenient/mycroft-core/.venv/lib/python3.8/site-packages/requests/adapters.py", line 529, in send
    raise ReadTimeout(e, request=request)
requests.exceptions.ReadTimeout: HTTPSConnectionPool(host='api.mycroft.ai', port=443): Read timed out. (read timeout=3.05)
2021-03-07 16:10:03.580 | WARNING  |  4936 | ConfigurationSkill | Failed to update settings, will retry later


//////////////////////////////////////////////////////////////////
//////////////////////////////////////////////////////////////////
//////////////////////////////////////////////////////////////////



ERROR 01: GPT2

Removing event fallback-query.mycroftai:QuestionQueryTimeout



//////////////////////////////////////////////////////////////////
//////////////////////////////////////////////////////////////////
//////////////////////////////////////////////////////////////////


ERROR 02: 
When Save files
>>>>>NORMAL CF WAY TO DO IT WITHIN MYCROFT 


//////////////////////////////////////////////////////////////////
//////////////////////////////////////////////////////////////////
//////////////////////////////////////////////////////////////////

ERROR 03:

When scrape online
Removing event fallback-query.mycroftai:QuestionQueryTimeout
>>>>>BUT CAN TRY WITHOUT API TO SCRAP URLS, NEED To uninstall googlle-api opr so because conflictive ?

=======================================================
Scraping Google results and get urls
2021-03-07 16:38:48.763 | INFO     |  4936 | googleapiclient.discovery | URL being requested: GET https://www.googleapis.com/discovery/v1/apis/customsearch/v1/rest
2021-03-07 16:38:49.993 | INFO     |  4936 | googleapiclient.discovery | URL being requested: GET https://customsearch.googleapis.com/customsearch/v1?q=tea+pi&cx=6b1aa6117d1440ce9&key=AIzaSyDhfG5n_c_M1sdasbA3O4x8D8fxeZ3FTs4&alt=json
=======================================================
Getting urls
=======================================================
Extracting the texts
Downloading https://www.sinosplice.com/life/archives/2017/09/05/what-is-tea-pi
2021-03-07 16:38:58.595 | INFO     |  4936 | QuestionsAnswersSkill | Searching for fungible
Removing event fallback-query.mycroftai:QuestionQueryTimeout
Removing event fallback-query.mycroftai:QuestionQueryTimeout
Removing event fallback-query.mycroftai:QuestionQueryTimeout
Removing event fallback-query.mycroftai:QuestionQueryTimeout
2021-03-07 16:38:59.049 | INFO     |  4936 | QuestionsAnswersSkill | Timeout occured check responses
==================Article Scraped=====================================
What is “Tea Pi”?

by John Pasden in language





//////////////////////////////////////////////////////////////////
//////////////////////////////////////////////////////////////////
//////////////////////////////////////////////////////////////////


ERROR 004:


//////////////////////////////////////////////////////////////////
//////////////////////////////////////////////////////////////////
//////////////////////////////////////////////////////////////////
